[2025-06-06T17:11:54.188+0000] {taskinstance.py:1171} INFO - Dependencies all met for <TaskInstance: P2M3_iriel_aureleo_DAG.post_to_elasticsearch manual__2025-06-06T17:10:52.272005+00:00 [queued]>
[2025-06-06T17:11:54.250+0000] {taskinstance.py:1171} INFO - Dependencies all met for <TaskInstance: P2M3_iriel_aureleo_DAG.post_to_elasticsearch manual__2025-06-06T17:10:52.272005+00:00 [queued]>
[2025-06-06T17:11:54.262+0000] {taskinstance.py:1368} INFO - 
--------------------------------------------------------------------------------
[2025-06-06T17:11:54.278+0000] {taskinstance.py:1369} INFO - Starting attempt 1 of 1
[2025-06-06T17:11:54.294+0000] {taskinstance.py:1370} INFO - 
--------------------------------------------------------------------------------
[2025-06-06T17:11:54.497+0000] {taskinstance.py:1389} INFO - Executing <Task(_PythonDecoratedOperator): post_to_elasticsearch> on 2025-06-06 17:10:52.272005+00:00
[2025-06-06T17:11:54.628+0000] {standard_task_runner.py:52} INFO - Started process 223 to run task
[2025-06-06T17:11:54.693+0000] {standard_task_runner.py:79} INFO - Running: ['***', 'tasks', 'run', 'P2M3_iriel_aureleo_DAG', 'post_to_elasticsearch', 'manual__2025-06-06T17:10:52.272005+00:00', '--job-id', '7', '--raw', '--subdir', 'DAGS_FOLDER/P2M3_iriel_aureleo_DAG.py', '--cfg-path', '/tmp/tmpv1oh6ksr', '--error-file', '/tmp/tmpjl5ni7ck']
[2025-06-06T17:11:54.739+0000] {standard_task_runner.py:80} INFO - Job 7: Subtask post_to_elasticsearch
[2025-06-06T17:11:55.119+0000] {task_command.py:371} INFO - Running <TaskInstance: P2M3_iriel_aureleo_DAG.post_to_elasticsearch manual__2025-06-06T17:10:52.272005+00:00 [running]> on host 39d263693a13
[2025-06-06T17:11:55.677+0000] {taskinstance.py:1583} INFO - Exporting the following env vars:
AIRFLOW_CTX_DAG_OWNER=Iriel Aureleo
AIRFLOW_CTX_DAG_ID=P2M3_iriel_aureleo_DAG
AIRFLOW_CTX_TASK_ID=post_to_elasticsearch
AIRFLOW_CTX_EXECUTION_DATE=2025-06-06T17:10:52.272005+00:00
AIRFLOW_CTX_TRY_NUMBER=1
AIRFLOW_CTX_DAG_RUN_ID=manual__2025-06-06T17:10:52.272005+00:00
[2025-06-06T17:12:06.015+0000] {base.py:299} WARNING - POST http://elasticsearch:9200/_bulk [status:N/A request:10.063s]
Traceback (most recent call last):
  File "/home/airflow/.local/lib/python3.7/site-packages/urllib3/connectionpool.py", line 449, in _make_request
    six.raise_from(e, None)
  File "<string>", line 3, in raise_from
  File "/home/airflow/.local/lib/python3.7/site-packages/urllib3/connectionpool.py", line 444, in _make_request
    httplib_response = conn.getresponse()
  File "/usr/local/lib/python3.7/http/client.py", line 1373, in getresponse
    response.begin()
  File "/usr/local/lib/python3.7/http/client.py", line 319, in begin
    version, status, reason = self._read_status()
  File "/usr/local/lib/python3.7/http/client.py", line 280, in _read_status
    line = str(self.fp.readline(_MAXLINE + 1), "iso-8859-1")
  File "/usr/local/lib/python3.7/socket.py", line 589, in readinto
    return self._sock.recv_into(b)
socket.timeout: timed out

During handling of the above exception, another exception occurred:

Traceback (most recent call last):
  File "/home/airflow/.local/lib/python3.7/site-packages/elasticsearch/connection/http_urllib3.py", line 252, in perform_request
    method, url, body, retries=Retry(False), headers=request_headers, **kw
  File "/home/airflow/.local/lib/python3.7/site-packages/urllib3/connectionpool.py", line 788, in urlopen
    method, url, error=e, _pool=self, _stacktrace=sys.exc_info()[2]
  File "/home/airflow/.local/lib/python3.7/site-packages/urllib3/util/retry.py", line 525, in increment
    raise six.reraise(type(error), error, _stacktrace)
  File "/home/airflow/.local/lib/python3.7/site-packages/urllib3/packages/six.py", line 770, in reraise
    raise value
  File "/home/airflow/.local/lib/python3.7/site-packages/urllib3/connectionpool.py", line 710, in urlopen
    chunked=chunked,
  File "/home/airflow/.local/lib/python3.7/site-packages/urllib3/connectionpool.py", line 451, in _make_request
    self._raise_timeout(err=e, url=url, timeout_value=read_timeout)
  File "/home/airflow/.local/lib/python3.7/site-packages/urllib3/connectionpool.py", line 341, in _raise_timeout
    self, url, "Read timed out. (read timeout=%s)" % timeout_value
urllib3.exceptions.ReadTimeoutError: HTTPConnectionPool(host='elasticsearch', port=9200): Read timed out. (read timeout=10)
[2025-06-06T17:12:06.031+0000] {taskinstance.py:1902} ERROR - Task failed with exception
Traceback (most recent call last):
  File "/home/airflow/.local/lib/python3.7/site-packages/urllib3/connectionpool.py", line 449, in _make_request
    six.raise_from(e, None)
  File "<string>", line 3, in raise_from
  File "/home/airflow/.local/lib/python3.7/site-packages/urllib3/connectionpool.py", line 444, in _make_request
    httplib_response = conn.getresponse()
  File "/usr/local/lib/python3.7/http/client.py", line 1373, in getresponse
    response.begin()
  File "/usr/local/lib/python3.7/http/client.py", line 319, in begin
    version, status, reason = self._read_status()
  File "/usr/local/lib/python3.7/http/client.py", line 280, in _read_status
    line = str(self.fp.readline(_MAXLINE + 1), "iso-8859-1")
  File "/usr/local/lib/python3.7/socket.py", line 589, in readinto
    return self._sock.recv_into(b)
socket.timeout: timed out

During handling of the above exception, another exception occurred:

Traceback (most recent call last):
  File "/home/airflow/.local/lib/python3.7/site-packages/elasticsearch/connection/http_urllib3.py", line 252, in perform_request
    method, url, body, retries=Retry(False), headers=request_headers, **kw
  File "/home/airflow/.local/lib/python3.7/site-packages/urllib3/connectionpool.py", line 788, in urlopen
    method, url, error=e, _pool=self, _stacktrace=sys.exc_info()[2]
  File "/home/airflow/.local/lib/python3.7/site-packages/urllib3/util/retry.py", line 525, in increment
    raise six.reraise(type(error), error, _stacktrace)
  File "/home/airflow/.local/lib/python3.7/site-packages/urllib3/packages/six.py", line 770, in reraise
    raise value
  File "/home/airflow/.local/lib/python3.7/site-packages/urllib3/connectionpool.py", line 710, in urlopen
    chunked=chunked,
  File "/home/airflow/.local/lib/python3.7/site-packages/urllib3/connectionpool.py", line 451, in _make_request
    self._raise_timeout(err=e, url=url, timeout_value=read_timeout)
  File "/home/airflow/.local/lib/python3.7/site-packages/urllib3/connectionpool.py", line 341, in _raise_timeout
    self, url, "Read timed out. (read timeout=%s)" % timeout_value
urllib3.exceptions.ReadTimeoutError: HTTPConnectionPool(host='elasticsearch', port=9200): Read timed out. (read timeout=10)

During handling of the above exception, another exception occurred:

Traceback (most recent call last):
  File "/home/airflow/.local/lib/python3.7/site-packages/airflow/decorators/base.py", line 179, in execute
    return_value = super().execute(context)
  File "/home/airflow/.local/lib/python3.7/site-packages/airflow/operators/python.py", line 171, in execute
    return_value = self.execute_callable()
  File "/home/airflow/.local/lib/python3.7/site-packages/airflow/operators/python.py", line 189, in execute_callable
    return self.python_callable(*self.op_args, **self.op_kwargs)
  File "/opt/airflow/dags/P2M3_iriel_aureleo_DAG.py", line 85, in post_to_elasticsearch
    helpers.bulk(es, actions)
  File "/home/airflow/.local/lib/python3.7/site-packages/elasticsearch/helpers/actions.py", line 411, in bulk
    client, actions, ignore_status=ignore_status, *args, **kwargs
  File "/home/airflow/.local/lib/python3.7/site-packages/elasticsearch/helpers/actions.py", line 339, in streaming_bulk
    **kwargs
  File "/home/airflow/.local/lib/python3.7/site-packages/elasticsearch/helpers/actions.py", line 256, in _process_bulk_chunk
    for item in gen:
  File "/home/airflow/.local/lib/python3.7/site-packages/elasticsearch/helpers/actions.py", line 195, in _process_bulk_chunk_error
    raise error
  File "/home/airflow/.local/lib/python3.7/site-packages/elasticsearch/helpers/actions.py", line 240, in _process_bulk_chunk
    resp = client.bulk("\n".join(bulk_actions) + "\n", *args, **kwargs)
  File "/home/airflow/.local/lib/python3.7/site-packages/elasticsearch/client/utils.py", line 168, in _wrapped
    return func(*args, params=params, headers=headers, **kwargs)
  File "/home/airflow/.local/lib/python3.7/site-packages/elasticsearch/client/__init__.py", line 468, in bulk
    body=body,
  File "/home/airflow/.local/lib/python3.7/site-packages/elasticsearch/transport.py", line 415, in perform_request
    raise e
  File "/home/airflow/.local/lib/python3.7/site-packages/elasticsearch/transport.py", line 388, in perform_request
    timeout=timeout,
  File "/home/airflow/.local/lib/python3.7/site-packages/elasticsearch/connection/http_urllib3.py", line 265, in perform_request
    raise ConnectionTimeout("TIMEOUT", str(e), e)
elasticsearch.exceptions.ConnectionTimeout: ConnectionTimeout caused by - ReadTimeoutError(HTTPConnectionPool(host='elasticsearch', port=9200): Read timed out. (read timeout=10))
[2025-06-06T17:12:06.259+0000] {taskinstance.py:1412} INFO - Marking task as FAILED. dag_id=P2M3_iriel_aureleo_DAG, task_id=post_to_elasticsearch, execution_date=20250606T171052, start_date=20250606T171154, end_date=20250606T171206
[2025-06-06T17:12:06.395+0000] {standard_task_runner.py:97} ERROR - Failed to execute job 7 for task post_to_elasticsearch (ConnectionTimeout caused by - ReadTimeoutError(HTTPConnectionPool(host='elasticsearch', port=9200): Read timed out. (read timeout=10)); 223)
[2025-06-06T17:12:06.506+0000] {local_task_job.py:156} INFO - Task exited with return code 1
[2025-06-06T17:12:07.268+0000] {local_task_job.py:279} INFO - 0 downstream tasks scheduled from follow-on schedule check
